# 비동기 에러 처리
- 비동기식으로 작동하는 콜백의 내부에서 발생한 에러는, 콜백 바깥에 있는 try 블록으로는 잡아낼 수 없다.
- 비동기 함수는 promise를 반환하고 일반적인 try...catch는 더이상 에러를 잡아 낼 수 없다.
- async극 promise를 보내고 코드는 더이상 이 코드를 기다리지 않기 떄문에 finall블록이 먼저 실행되고 그 후에 promise가 실행되기 떄문이다
- ``` js
    async function thisThrows() {
        throw new Error("Thrown from thisThrows()");
    }

    try {
        thisThrows();
    } catch (e) {
        console.error(e);
    } finally {
        console.log('We do cleanup here');
    }

    // output:
    // We do cleanup here
    // UnhandledPromiseRejectionWarning: Error: Thrown from thisThrows()

## __<span style="color:#9999ff">해결 방법</span>__
### __<span style="color:#ff9933">await 이용</span>__
- async 함수를 하나 만들고 await로 기다리게 한다.
- ``` js
    async function func() {
    try {
        const res = await fetch('https://nonexistent-domain.nowhere');
    } catch (e) {
        console.log(e.message);
    }
    }

    func(); // 출력 결과: Failed to fetch

### __<span style="color:#ff9933">catch 사용</span>__
- promise의 cath메소드를 사용한다.
- ``` js
    p.then(even => {
    return '짝수입니다.';
    }).catch(e => {
    return e.message;
    }).then(alert);

# 참고
- https://helloworldjavascript.net/pages/290-exception.html
- https://velog.io/@haujinnn/async%EC%99%80-await%EB%A5%BC-%ED%86%B5%ED%95%9C-JS-%EC%97%90%EB%9F%AC-%EC%B2%98%EB%A6%ACerror-handling